[2024-03-24T16:35:34.869+0000] {taskinstance.py:1979} INFO - Dependencies all met for dep_context=non-requeueable deps ti=<TaskInstance: tomtom.export_data_to_db scheduled__2024-03-18T00:00:00+00:00 [queued]>
[2024-03-24T16:35:34.886+0000] {taskinstance.py:1979} INFO - Dependencies all met for dep_context=requeueable deps ti=<TaskInstance: tomtom.export_data_to_db scheduled__2024-03-18T00:00:00+00:00 [queued]>
[2024-03-24T16:35:34.887+0000] {taskinstance.py:2193} INFO - Starting attempt 2 of 2
[2024-03-24T16:35:34.926+0000] {taskinstance.py:2217} INFO - Executing <Task(BashOperator): export_data_to_db> on 2024-03-18 00:00:00+00:00
[2024-03-24T16:35:34.938+0000] {standard_task_runner.py:60} INFO - Started process 571 to run task
[2024-03-24T16:35:34.950+0000] {standard_task_runner.py:87} INFO - Running: ['***', 'tasks', 'run', 'tomtom', 'export_data_to_db', 'scheduled__2024-03-18T00:00:00+00:00', '--job-id', '15', '--raw', '--subdir', 'DAGS_FOLDER/tomtom_dag.py', '--cfg-path', '/tmp/tmpia7zmdt6']
[2024-03-24T16:35:34.955+0000] {standard_task_runner.py:88} INFO - Job 15: Subtask export_data_to_db
[2024-03-24T16:35:35.028+0000] {logging_mixin.py:188} WARNING - /home/***/.local/lib/python3.8/site-packages/***/settings.py:194 DeprecationWarning: The sql_alchemy_conn option in [core] has been moved to the sql_alchemy_conn option in [database] - the old setting has been used, but please update your config.
[2024-03-24T16:35:36.234+0000] {task_command.py:423} INFO - Running <TaskInstance: tomtom.export_data_to_db scheduled__2024-03-18T00:00:00+00:00 [running]> on host cc0f04bb20f0
[2024-03-24T16:35:36.635+0000] {taskinstance.py:2513} INFO - Exporting env vars: AIRFLOW_CTX_DAG_OWNER='***' AIRFLOW_CTX_DAG_ID='tomtom' AIRFLOW_CTX_TASK_ID='export_data_to_db' AIRFLOW_CTX_EXECUTION_DATE='2024-03-18T00:00:00+00:00' AIRFLOW_CTX_TRY_NUMBER='2' AIRFLOW_CTX_DAG_RUN_ID='scheduled__2024-03-18T00:00:00+00:00'
[2024-03-24T16:35:36.647+0000] {subprocess.py:63} INFO - Tmp dir root location: /tmp
[2024-03-24T16:35:36.658+0000] {subprocess.py:75} INFO - Running command: ['/usr/bin/bash', '-c', 'python /opt/***/dags/tomtom_to_db.py --date 2024-03-18 --connection postgresql+psycopg2://***:***@postgres/***']
[2024-03-24T16:35:36.713+0000] {subprocess.py:86} INFO - Output:
[2024-03-24T16:35:38.346+0000] {subprocess.py:93} INFO - Traceback (most recent call last):
[2024-03-24T16:35:38.354+0000] {subprocess.py:93} INFO -   File "/opt/***/dags/tomtom_to_db.py", line 53, in <module>
[2024-03-24T16:35:38.357+0000] {subprocess.py:93} INFO -     main(args.date, args.connection)
[2024-03-24T16:35:38.360+0000] {subprocess.py:93} INFO -   File "/opt/***/dags/tomtom_to_db.py", line 28, in main
[2024-03-24T16:35:38.364+0000] {subprocess.py:93} INFO -     with open(filename, encoding='utf-8') as csvf:
[2024-03-24T16:35:38.368+0000] {subprocess.py:93} INFO - FileNotFoundError: [Errno 2] No such file or directory: '/opt/***/dags/datasets/tomtom/tomtom_2024-03-17.csv'
[2024-03-24T16:35:38.497+0000] {subprocess.py:97} INFO - Command exited with return code 1
[2024-03-24T16:35:38.524+0000] {taskinstance.py:2731} ERROR - Task failed with exception
Traceback (most recent call last):
  File "/home/airflow/.local/lib/python3.8/site-packages/airflow/models/taskinstance.py", line 444, in _execute_task
    result = _execute_callable(context=context, **execute_callable_kwargs)
  File "/home/airflow/.local/lib/python3.8/site-packages/airflow/models/taskinstance.py", line 414, in _execute_callable
    return execute_callable(context=context, **execute_callable_kwargs)
  File "/home/airflow/.local/lib/python3.8/site-packages/airflow/operators/bash.py", line 212, in execute
    raise AirflowException(
airflow.exceptions.AirflowException: Bash command failed. The command returned a non-zero exit code 1.
[2024-03-24T16:35:38.540+0000] {taskinstance.py:1149} INFO - Marking task as FAILED. dag_id=tomtom, task_id=export_data_to_db, execution_date=20240318T000000, start_date=20240324T163534, end_date=20240324T163538
[2024-03-24T16:35:38.626+0000] {standard_task_runner.py:107} ERROR - Failed to execute job 15 for task export_data_to_db (Bash command failed. The command returned a non-zero exit code 1.; 571)
[2024-03-24T16:35:38.837+0000] {local_task_job_runner.py:234} INFO - Task exited with return code 1
[2024-03-24T16:35:38.980+0000] {taskinstance.py:3312} INFO - 0 downstream tasks scheduled from follow-on schedule check
[2024-03-24T16:55:45.521+0000] {taskinstance.py:1979} INFO - Dependencies all met for dep_context=non-requeueable deps ti=<TaskInstance: tomtom.export_data_to_db scheduled__2024-03-18T00:00:00+00:00 [queued]>
[2024-03-24T16:55:45.539+0000] {taskinstance.py:1979} INFO - Dependencies all met for dep_context=requeueable deps ti=<TaskInstance: tomtom.export_data_to_db scheduled__2024-03-18T00:00:00+00:00 [queued]>
[2024-03-24T16:55:45.541+0000] {taskinstance.py:2193} INFO - Starting attempt 2 of 2
[2024-03-24T16:55:45.559+0000] {taskinstance.py:2217} INFO - Executing <Task(BashOperator): export_data_to_db> on 2024-03-18 00:00:00+00:00
[2024-03-24T16:55:45.568+0000] {standard_task_runner.py:60} INFO - Started process 481 to run task
[2024-03-24T16:55:45.575+0000] {standard_task_runner.py:87} INFO - Running: ['***', 'tasks', 'run', 'tomtom', 'export_data_to_db', 'scheduled__2024-03-18T00:00:00+00:00', '--job-id', '15', '--raw', '--subdir', 'DAGS_FOLDER/tomtom_dag.py', '--cfg-path', '/tmp/tmp0c36edj8']
[2024-03-24T16:55:45.580+0000] {standard_task_runner.py:88} INFO - Job 15: Subtask export_data_to_db
[2024-03-24T16:55:45.613+0000] {logging_mixin.py:188} WARNING - /home/***/.local/lib/python3.8/site-packages/***/settings.py:194 DeprecationWarning: The sql_alchemy_conn option in [core] has been moved to the sql_alchemy_conn option in [database] - the old setting has been used, but please update your config.
[2024-03-24T16:55:45.692+0000] {task_command.py:423} INFO - Running <TaskInstance: tomtom.export_data_to_db scheduled__2024-03-18T00:00:00+00:00 [running]> on host 1ef4dfe662c6
[2024-03-24T16:55:45.826+0000] {taskinstance.py:2513} INFO - Exporting env vars: AIRFLOW_CTX_DAG_OWNER='***' AIRFLOW_CTX_DAG_ID='tomtom' AIRFLOW_CTX_TASK_ID='export_data_to_db' AIRFLOW_CTX_EXECUTION_DATE='2024-03-18T00:00:00+00:00' AIRFLOW_CTX_TRY_NUMBER='2' AIRFLOW_CTX_DAG_RUN_ID='scheduled__2024-03-18T00:00:00+00:00'
[2024-03-24T16:55:45.829+0000] {subprocess.py:63} INFO - Tmp dir root location: /tmp
[2024-03-24T16:55:45.831+0000] {subprocess.py:75} INFO - Running command: ['/usr/bin/bash', '-c', 'python /opt/***/dags/tomtom_to_db.py --date 2024-03-18 --connection postgresql+psycopg2://***:***@postgres/***']
[2024-03-24T16:55:45.847+0000] {subprocess.py:86} INFO - Output:
[2024-03-24T16:55:46.215+0000] {subprocess.py:93} INFO - Traceback (most recent call last):
[2024-03-24T16:55:46.217+0000] {subprocess.py:93} INFO -   File "/opt/***/dags/tomtom_to_db.py", line 53, in <module>
[2024-03-24T16:55:46.219+0000] {subprocess.py:93} INFO -     main(args.date, args.connection)
[2024-03-24T16:55:46.222+0000] {subprocess.py:93} INFO -   File "/opt/***/dags/tomtom_to_db.py", line 28, in main
[2024-03-24T16:55:46.223+0000] {subprocess.py:93} INFO -     with open(filename, encoding='utf-8') as csvf:
[2024-03-24T16:55:46.226+0000] {subprocess.py:93} INFO - FileNotFoundError: [Errno 2] No such file or directory: '/opt/***/dags/datasets/tomtom/tomtom_2024-03-17.csv'
[2024-03-24T16:55:46.289+0000] {subprocess.py:97} INFO - Command exited with return code 1
[2024-03-24T16:55:46.319+0000] {taskinstance.py:2731} ERROR - Task failed with exception
Traceback (most recent call last):
  File "/home/airflow/.local/lib/python3.8/site-packages/airflow/models/taskinstance.py", line 444, in _execute_task
    result = _execute_callable(context=context, **execute_callable_kwargs)
  File "/home/airflow/.local/lib/python3.8/site-packages/airflow/models/taskinstance.py", line 414, in _execute_callable
    return execute_callable(context=context, **execute_callable_kwargs)
  File "/home/airflow/.local/lib/python3.8/site-packages/airflow/operators/bash.py", line 212, in execute
    raise AirflowException(
airflow.exceptions.AirflowException: Bash command failed. The command returned a non-zero exit code 1.
[2024-03-24T16:55:46.325+0000] {taskinstance.py:1149} INFO - Marking task as FAILED. dag_id=tomtom, task_id=export_data_to_db, execution_date=20240318T000000, start_date=20240324T165545, end_date=20240324T165546
[2024-03-24T16:55:46.346+0000] {standard_task_runner.py:107} ERROR - Failed to execute job 15 for task export_data_to_db (Bash command failed. The command returned a non-zero exit code 1.; 481)
[2024-03-24T16:55:46.398+0000] {local_task_job_runner.py:234} INFO - Task exited with return code 1
[2024-03-24T16:55:46.431+0000] {taskinstance.py:3312} INFO - 0 downstream tasks scheduled from follow-on schedule check
