[2024-03-24T16:30:27.028+0000] {taskinstance.py:1979} INFO - Dependencies all met for dep_context=non-requeueable deps ti=<TaskInstance: tomtom.export_data_to_db scheduled__2024-03-18T00:00:00+00:00 [queued]>
[2024-03-24T16:30:27.113+0000] {taskinstance.py:1979} INFO - Dependencies all met for dep_context=requeueable deps ti=<TaskInstance: tomtom.export_data_to_db scheduled__2024-03-18T00:00:00+00:00 [queued]>
[2024-03-24T16:30:27.115+0000] {taskinstance.py:2193} INFO - Starting attempt 1 of 2
[2024-03-24T16:30:27.203+0000] {taskinstance.py:2217} INFO - Executing <Task(BashOperator): export_data_to_db> on 2024-03-18 00:00:00+00:00
[2024-03-24T16:30:27.222+0000] {standard_task_runner.py:60} INFO - Started process 407 to run task
[2024-03-24T16:30:27.282+0000] {standard_task_runner.py:87} INFO - Running: ['***', 'tasks', 'run', 'tomtom', 'export_data_to_db', 'scheduled__2024-03-18T00:00:00+00:00', '--job-id', '14', '--raw', '--subdir', 'DAGS_FOLDER/tomtom_dag.py', '--cfg-path', '/tmp/tmpk64cspqt']
[2024-03-24T16:30:27.304+0000] {standard_task_runner.py:88} INFO - Job 14: Subtask export_data_to_db
[2024-03-24T16:30:27.451+0000] {logging_mixin.py:188} WARNING - /home/***/.local/lib/python3.8/site-packages/***/settings.py:194 DeprecationWarning: The sql_alchemy_conn option in [core] has been moved to the sql_alchemy_conn option in [database] - the old setting has been used, but please update your config.
[2024-03-24T16:30:27.714+0000] {task_command.py:423} INFO - Running <TaskInstance: tomtom.export_data_to_db scheduled__2024-03-18T00:00:00+00:00 [running]> on host cc0f04bb20f0
[2024-03-24T16:30:28.171+0000] {taskinstance.py:2513} INFO - Exporting env vars: AIRFLOW_CTX_DAG_OWNER='***' AIRFLOW_CTX_DAG_ID='tomtom' AIRFLOW_CTX_TASK_ID='export_data_to_db' AIRFLOW_CTX_EXECUTION_DATE='2024-03-18T00:00:00+00:00' AIRFLOW_CTX_TRY_NUMBER='1' AIRFLOW_CTX_DAG_RUN_ID='scheduled__2024-03-18T00:00:00+00:00'
[2024-03-24T16:30:28.174+0000] {subprocess.py:63} INFO - Tmp dir root location: /tmp
[2024-03-24T16:30:28.177+0000] {subprocess.py:75} INFO - Running command: ['/usr/bin/bash', '-c', 'python /opt/***/dags/tomtom_to_db.py --date 2024-03-18 --connection postgresql+psycopg2://***:***@postgres/***']
[2024-03-24T16:30:28.212+0000] {subprocess.py:86} INFO - Output:
[2024-03-24T16:30:29.951+0000] {subprocess.py:93} INFO - Traceback (most recent call last):
[2024-03-24T16:30:29.953+0000] {subprocess.py:93} INFO -   File "/opt/***/dags/tomtom_to_db.py", line 53, in <module>
[2024-03-24T16:30:29.955+0000] {subprocess.py:93} INFO -     main(args.date, args.connection)
[2024-03-24T16:30:29.958+0000] {subprocess.py:93} INFO -   File "/opt/***/dags/tomtom_to_db.py", line 28, in main
[2024-03-24T16:30:29.959+0000] {subprocess.py:93} INFO -     with open(filename, encoding='utf-8') as csvf:
[2024-03-24T16:30:29.962+0000] {subprocess.py:93} INFO - FileNotFoundError: [Errno 2] No such file or directory: '/opt/***/dags/datasets/tomtom/tomtom_2024-03-17.csv'
[2024-03-24T16:30:30.242+0000] {subprocess.py:97} INFO - Command exited with return code 1
[2024-03-24T16:30:30.340+0000] {taskinstance.py:2731} ERROR - Task failed with exception
Traceback (most recent call last):
  File "/home/airflow/.local/lib/python3.8/site-packages/airflow/models/taskinstance.py", line 444, in _execute_task
    result = _execute_callable(context=context, **execute_callable_kwargs)
  File "/home/airflow/.local/lib/python3.8/site-packages/airflow/models/taskinstance.py", line 414, in _execute_callable
    return execute_callable(context=context, **execute_callable_kwargs)
  File "/home/airflow/.local/lib/python3.8/site-packages/airflow/operators/bash.py", line 212, in execute
    raise AirflowException(
airflow.exceptions.AirflowException: Bash command failed. The command returned a non-zero exit code 1.
[2024-03-24T16:30:30.392+0000] {taskinstance.py:1149} INFO - Marking task as UP_FOR_RETRY. dag_id=tomtom, task_id=export_data_to_db, execution_date=20240318T000000, start_date=20240324T163027, end_date=20240324T163030
[2024-03-24T16:30:30.551+0000] {standard_task_runner.py:107} ERROR - Failed to execute job 14 for task export_data_to_db (Bash command failed. The command returned a non-zero exit code 1.; 407)
[2024-03-24T16:30:30.628+0000] {local_task_job_runner.py:234} INFO - Task exited with return code 1
[2024-03-24T16:30:30.741+0000] {taskinstance.py:3312} INFO - 0 downstream tasks scheduled from follow-on schedule check
[2024-03-24T16:50:40.855+0000] {taskinstance.py:1979} INFO - Dependencies all met for dep_context=non-requeueable deps ti=<TaskInstance: tomtom.export_data_to_db scheduled__2024-03-18T00:00:00+00:00 [queued]>
[2024-03-24T16:50:40.947+0000] {taskinstance.py:1979} INFO - Dependencies all met for dep_context=requeueable deps ti=<TaskInstance: tomtom.export_data_to_db scheduled__2024-03-18T00:00:00+00:00 [queued]>
[2024-03-24T16:50:40.950+0000] {taskinstance.py:2193} INFO - Starting attempt 1 of 2
[2024-03-24T16:50:41.060+0000] {taskinstance.py:2217} INFO - Executing <Task(BashOperator): export_data_to_db> on 2024-03-18 00:00:00+00:00
[2024-03-24T16:50:41.088+0000] {standard_task_runner.py:60} INFO - Started process 312 to run task
[2024-03-24T16:50:41.140+0000] {standard_task_runner.py:87} INFO - Running: ['***', 'tasks', 'run', 'tomtom', 'export_data_to_db', 'scheduled__2024-03-18T00:00:00+00:00', '--job-id', '9', '--raw', '--subdir', 'DAGS_FOLDER/tomtom_dag.py', '--cfg-path', '/tmp/tmpkin48rp2']
[2024-03-24T16:50:41.161+0000] {standard_task_runner.py:88} INFO - Job 9: Subtask export_data_to_db
[2024-03-24T16:50:41.286+0000] {logging_mixin.py:188} WARNING - /home/***/.local/lib/python3.8/site-packages/***/settings.py:194 DeprecationWarning: The sql_alchemy_conn option in [core] has been moved to the sql_alchemy_conn option in [database] - the old setting has been used, but please update your config.
[2024-03-24T16:50:41.445+0000] {task_command.py:423} INFO - Running <TaskInstance: tomtom.export_data_to_db scheduled__2024-03-18T00:00:00+00:00 [running]> on host 1ef4dfe662c6
[2024-03-24T16:50:41.826+0000] {taskinstance.py:2513} INFO - Exporting env vars: AIRFLOW_CTX_DAG_OWNER='***' AIRFLOW_CTX_DAG_ID='tomtom' AIRFLOW_CTX_TASK_ID='export_data_to_db' AIRFLOW_CTX_EXECUTION_DATE='2024-03-18T00:00:00+00:00' AIRFLOW_CTX_TRY_NUMBER='1' AIRFLOW_CTX_DAG_RUN_ID='scheduled__2024-03-18T00:00:00+00:00'
[2024-03-24T16:50:41.829+0000] {subprocess.py:63} INFO - Tmp dir root location: /tmp
[2024-03-24T16:50:41.838+0000] {subprocess.py:75} INFO - Running command: ['/usr/bin/bash', '-c', 'python /opt/***/dags/tomtom_to_db.py --date 2024-03-18 --connection postgresql+psycopg2://***:***@postgres/***']
[2024-03-24T16:50:41.900+0000] {subprocess.py:86} INFO - Output:
[2024-03-24T16:50:43.835+0000] {subprocess.py:93} INFO - Traceback (most recent call last):
[2024-03-24T16:50:43.836+0000] {subprocess.py:93} INFO -   File "/opt/***/dags/tomtom_to_db.py", line 53, in <module>
[2024-03-24T16:50:43.838+0000] {subprocess.py:93} INFO -     main(args.date, args.connection)
[2024-03-24T16:50:43.841+0000] {subprocess.py:93} INFO -   File "/opt/***/dags/tomtom_to_db.py", line 28, in main
[2024-03-24T16:50:43.842+0000] {subprocess.py:93} INFO -     with open(filename, encoding='utf-8') as csvf:
[2024-03-24T16:50:43.844+0000] {subprocess.py:93} INFO - FileNotFoundError: [Errno 2] No such file or directory: '/opt/***/dags/datasets/tomtom/tomtom_2024-03-17.csv'
[2024-03-24T16:50:44.081+0000] {subprocess.py:97} INFO - Command exited with return code 1
[2024-03-24T16:50:44.129+0000] {taskinstance.py:2731} ERROR - Task failed with exception
Traceback (most recent call last):
  File "/home/airflow/.local/lib/python3.8/site-packages/airflow/models/taskinstance.py", line 444, in _execute_task
    result = _execute_callable(context=context, **execute_callable_kwargs)
  File "/home/airflow/.local/lib/python3.8/site-packages/airflow/models/taskinstance.py", line 414, in _execute_callable
    return execute_callable(context=context, **execute_callable_kwargs)
  File "/home/airflow/.local/lib/python3.8/site-packages/airflow/operators/bash.py", line 212, in execute
    raise AirflowException(
airflow.exceptions.AirflowException: Bash command failed. The command returned a non-zero exit code 1.
[2024-03-24T16:50:44.148+0000] {taskinstance.py:1149} INFO - Marking task as UP_FOR_RETRY. dag_id=tomtom, task_id=export_data_to_db, execution_date=20240318T000000, start_date=20240324T165040, end_date=20240324T165044
[2024-03-24T16:50:44.321+0000] {standard_task_runner.py:107} ERROR - Failed to execute job 9 for task export_data_to_db (Bash command failed. The command returned a non-zero exit code 1.; 312)
[2024-03-24T16:50:44.383+0000] {local_task_job_runner.py:234} INFO - Task exited with return code 1
[2024-03-24T16:50:44.469+0000] {taskinstance.py:3312} INFO - 0 downstream tasks scheduled from follow-on schedule check
[2024-03-24T17:29:08.479+0000] {taskinstance.py:1979} INFO - Dependencies all met for dep_context=non-requeueable deps ti=<TaskInstance: tomtom.export_data_to_db scheduled__2024-03-18T00:00:00+00:00 [queued]>
[2024-03-24T17:29:08.830+0000] {taskinstance.py:1979} INFO - Dependencies all met for dep_context=requeueable deps ti=<TaskInstance: tomtom.export_data_to_db scheduled__2024-03-18T00:00:00+00:00 [queued]>
[2024-03-24T17:29:08.847+0000] {taskinstance.py:2193} INFO - Starting attempt 1 of 2
[2024-03-24T17:29:09.387+0000] {taskinstance.py:2217} INFO - Executing <Task(BashOperator): export_data_to_db> on 2024-03-18 00:00:00+00:00
[2024-03-24T17:29:09.412+0000] {standard_task_runner.py:60} INFO - Started process 345 to run task
[2024-03-24T17:29:09.451+0000] {standard_task_runner.py:87} INFO - Running: ['***', 'tasks', 'run', 'tomtom', 'export_data_to_db', 'scheduled__2024-03-18T00:00:00+00:00', '--job-id', '10', '--raw', '--subdir', 'DAGS_FOLDER/tomtom_dag.py', '--cfg-path', '/tmp/tmpzdw3tj96']
[2024-03-24T17:29:09.473+0000] {standard_task_runner.py:88} INFO - Job 10: Subtask export_data_to_db
[2024-03-24T17:29:09.601+0000] {logging_mixin.py:188} WARNING - /home/***/.local/lib/python3.8/site-packages/***/settings.py:194 DeprecationWarning: The sql_alchemy_conn option in [core] has been moved to the sql_alchemy_conn option in [database] - the old setting has been used, but please update your config.
[2024-03-24T17:29:09.911+0000] {task_command.py:423} INFO - Running <TaskInstance: tomtom.export_data_to_db scheduled__2024-03-18T00:00:00+00:00 [running]> on host 77fbfb9df273
[2024-03-24T17:29:10.512+0000] {taskinstance.py:2513} INFO - Exporting env vars: AIRFLOW_CTX_DAG_OWNER='***' AIRFLOW_CTX_DAG_ID='tomtom' AIRFLOW_CTX_TASK_ID='export_data_to_db' AIRFLOW_CTX_EXECUTION_DATE='2024-03-18T00:00:00+00:00' AIRFLOW_CTX_TRY_NUMBER='1' AIRFLOW_CTX_DAG_RUN_ID='scheduled__2024-03-18T00:00:00+00:00'
[2024-03-24T17:29:10.515+0000] {subprocess.py:63} INFO - Tmp dir root location: /tmp
[2024-03-24T17:29:10.530+0000] {subprocess.py:75} INFO - Running command: ['/usr/bin/bash', '-c', 'python /opt/***/dags/tomtom_to_db.py --date 2024-03-18 --connection postgresql+psycopg2://***:***@postgres/***']
[2024-03-24T17:29:10.611+0000] {subprocess.py:86} INFO - Output:
[2024-03-24T17:29:12.133+0000] {subprocess.py:93} INFO - Traceback (most recent call last):
[2024-03-24T17:29:12.135+0000] {subprocess.py:93} INFO -   File "/opt/***/dags/tomtom_to_db.py", line 53, in <module>
[2024-03-24T17:29:12.137+0000] {subprocess.py:93} INFO -     main(args.date, args.connection)
[2024-03-24T17:29:12.139+0000] {subprocess.py:93} INFO -   File "/opt/***/dags/tomtom_to_db.py", line 28, in main
[2024-03-24T17:29:12.143+0000] {subprocess.py:93} INFO -     with open(filename, encoding='utf-8') as csvf:
[2024-03-24T17:29:12.144+0000] {subprocess.py:93} INFO - FileNotFoundError: [Errno 2] No such file or directory: '/opt/***/dags/datasets/tomtom/tomtom_2024-03-17.csv'
[2024-03-24T17:29:12.460+0000] {subprocess.py:97} INFO - Command exited with return code 1
[2024-03-24T17:29:12.510+0000] {taskinstance.py:2731} ERROR - Task failed with exception
Traceback (most recent call last):
  File "/home/airflow/.local/lib/python3.8/site-packages/airflow/models/taskinstance.py", line 444, in _execute_task
    result = _execute_callable(context=context, **execute_callable_kwargs)
  File "/home/airflow/.local/lib/python3.8/site-packages/airflow/models/taskinstance.py", line 414, in _execute_callable
    return execute_callable(context=context, **execute_callable_kwargs)
  File "/home/airflow/.local/lib/python3.8/site-packages/airflow/operators/bash.py", line 212, in execute
    raise AirflowException(
airflow.exceptions.AirflowException: Bash command failed. The command returned a non-zero exit code 1.
[2024-03-24T17:29:12.537+0000] {taskinstance.py:1149} INFO - Marking task as UP_FOR_RETRY. dag_id=tomtom, task_id=export_data_to_db, execution_date=20240318T000000, start_date=20240324T172908, end_date=20240324T172912
[2024-03-24T17:29:12.659+0000] {standard_task_runner.py:107} ERROR - Failed to execute job 10 for task export_data_to_db (Bash command failed. The command returned a non-zero exit code 1.; 345)
[2024-03-24T17:29:12.779+0000] {local_task_job_runner.py:234} INFO - Task exited with return code 1
[2024-03-24T17:29:13.055+0000] {taskinstance.py:3312} INFO - 0 downstream tasks scheduled from follow-on schedule check
